 function catchError(fn) {
     return function(req,res,next) {
         fn(req,res,next).catch(next);
     };
 }
  module.exports.catchError = catchError;

